[2024-11-10T15:47:08.794+0000] {local_task_job_runner.py:123} INFO - ::group::Pre task execution logs
[2024-11-10T15:47:08.809+0000] {taskinstance.py:2612} INFO - Dependencies all met for dep_context=non-requeueable deps ti=<TaskInstance: html_email_template_on_failure.failing_task manual__2024-11-10T15:47:07.976396+00:00 [queued]>
[2024-11-10T15:47:08.819+0000] {taskinstance.py:2612} INFO - Dependencies all met for dep_context=requeueable deps ti=<TaskInstance: html_email_template_on_failure.failing_task manual__2024-11-10T15:47:07.976396+00:00 [queued]>
[2024-11-10T15:47:08.820+0000] {taskinstance.py:2865} INFO - Starting attempt 1 of 2
[2024-11-10T15:47:08.830+0000] {taskinstance.py:2888} INFO - Executing <Task(PythonOperator): failing_task> on 2024-11-10 15:47:07.976396+00:00
[2024-11-10T15:47:08.837+0000] {warnings.py:112} WARNING - /home/***/.local/lib/python3.12/site-packages/***/task/task_runner/standard_task_runner.py:70: DeprecationWarning: This process (pid=900) is multi-threaded, use of fork() may lead to deadlocks in the child.
  pid = os.fork()

[2024-11-10T15:47:08.838+0000] {standard_task_runner.py:72} INFO - Started process 901 to run task
[2024-11-10T15:47:08.839+0000] {standard_task_runner.py:104} INFO - Running: ['***', 'tasks', 'run', 'html_email_template_on_failure', 'failing_task', 'manual__2024-11-10T15:47:07.976396+00:00', '--job-id', '63', '--raw', '--subdir', 'DAGS_FOLDER/emailalert_dag.py', '--cfg-path', '/tmp/tmppv4v1e3i']
[2024-11-10T15:47:08.839+0000] {standard_task_runner.py:105} INFO - Job 63: Subtask failing_task
[2024-11-10T15:47:08.872+0000] {task_command.py:467} INFO - Running <TaskInstance: html_email_template_on_failure.failing_task manual__2024-11-10T15:47:07.976396+00:00 [running]> on host 5dee1e87bc96
[2024-11-10T15:47:08.929+0000] {taskinstance.py:3131} INFO - Exporting env vars: AIRFLOW_CTX_DAG_OWNER='***' AIRFLOW_CTX_DAG_ID='html_email_template_on_failure' AIRFLOW_CTX_TASK_ID='failing_task' AIRFLOW_CTX_EXECUTION_DATE='2024-11-10T15:47:07.976396+00:00' AIRFLOW_CTX_TRY_NUMBER='1' AIRFLOW_CTX_DAG_RUN_ID='manual__2024-11-10T15:47:07.976396+00:00'
[2024-11-10T15:47:08.930+0000] {taskinstance.py:731} INFO - ::endgroup::
[2024-11-10T15:47:08.940+0000] {taskinstance.py:3310} ERROR - Task failed with exception
Traceback (most recent call last):
  File "/home/airflow/.local/lib/python3.12/site-packages/airflow/models/taskinstance.py", line 767, in _execute_task
    result = _execute_callable(context=context, **execute_callable_kwargs)
             ^^^^^^^^^^^^^^^^^^^^^^^^^^^^^^^^^^^^^^^^^^^^^^^^^^^^^^^^^^^^^
  File "/home/airflow/.local/lib/python3.12/site-packages/airflow/models/taskinstance.py", line 733, in _execute_callable
    return ExecutionCallableRunner(
           ^^^^^^^^^^^^^^^^^^^^^^^^
  File "/home/airflow/.local/lib/python3.12/site-packages/airflow/utils/operator_helpers.py", line 252, in run
    return self.func(*args, **kwargs)
           ^^^^^^^^^^^^^^^^^^^^^^^^^^
  File "/home/airflow/.local/lib/python3.12/site-packages/airflow/models/baseoperator.py", line 406, in wrapper
    return func(self, *args, **kwargs)
           ^^^^^^^^^^^^^^^^^^^^^^^^^^^
  File "/home/airflow/.local/lib/python3.12/site-packages/airflow/operators/python.py", line 238, in execute
    return_value = self.execute_callable()
                   ^^^^^^^^^^^^^^^^^^^^^^^
  File "/home/airflow/.local/lib/python3.12/site-packages/airflow/operators/python.py", line 256, in execute_callable
    return runner.run(*self.op_args, **self.op_kwargs)
           ^^^^^^^^^^^^^^^^^^^^^^^^^^^^^^^^^^^^^^^^^^^
  File "/home/airflow/.local/lib/python3.12/site-packages/airflow/utils/operator_helpers.py", line 252, in run
    return self.func(*args, **kwargs)
           ^^^^^^^^^^^^^^^^^^^^^^^^^^
  File "/opt/airflow/dags/emailalert_dag.py", line 104, in sample_task
    raise ValueError("This task is meant to fail for testing purposes")
ValueError: This task is meant to fail for testing purposes
[2024-11-10T15:47:08.951+0000] {taskinstance.py:1225} INFO - Marking task as UP_FOR_RETRY. dag_id=html_email_template_on_failure, task_id=failing_task, run_id=manual__2024-11-10T15:47:07.976396+00:00, execution_date=20241110T154707, start_date=20241110T154708, end_date=20241110T154708
[2024-11-10T15:47:08.962+0000] {taskinstance.py:340} INFO - ::group::Post task execution logs
[2024-11-10T15:47:08.962+0000] {standard_task_runner.py:124} ERROR - Failed to execute job 63 for task failing_task (This task is meant to fail for testing purposes; 901)
Traceback (most recent call last):
  File "/home/airflow/.local/lib/python3.12/site-packages/airflow/task/task_runner/standard_task_runner.py", line 117, in _start_by_fork
    ret = args.func(args, dag=self.dag)
          ^^^^^^^^^^^^^^^^^^^^^^^^^^^^^
  File "/home/airflow/.local/lib/python3.12/site-packages/airflow/cli/cli_config.py", line 49, in command
    return func(*args, **kwargs)
           ^^^^^^^^^^^^^^^^^^^^^
  File "/home/airflow/.local/lib/python3.12/site-packages/airflow/utils/cli.py", line 115, in wrapper
    return f(*args, **kwargs)
           ^^^^^^^^^^^^^^^^^^
  File "/home/airflow/.local/lib/python3.12/site-packages/airflow/cli/commands/task_command.py", line 483, in task_run
    task_return_code = _run_task_by_selected_method(args, _dag, ti)
                       ^^^^^^^^^^^^^^^^^^^^^^^^^^^^^^^^^^^^^^^^^^^^
  File "/home/airflow/.local/lib/python3.12/site-packages/airflow/cli/commands/task_command.py", line 256, in _run_task_by_selected_method
    return _run_raw_task(args, ti)
           ^^^^^^^^^^^^^^^^^^^^^^^
  File "/home/airflow/.local/lib/python3.12/site-packages/airflow/cli/commands/task_command.py", line 341, in _run_raw_task
    return ti._run_raw_task(
           ^^^^^^^^^^^^^^^^^
  File "/home/airflow/.local/lib/python3.12/site-packages/airflow/utils/session.py", line 97, in wrapper
    return func(*args, session=session, **kwargs)
           ^^^^^^^^^^^^^^^^^^^^^^^^^^^^^^^^^^^^^^
  File "/home/airflow/.local/lib/python3.12/site-packages/airflow/models/taskinstance.py", line 3004, in _run_raw_task
    return _run_raw_task(
           ^^^^^^^^^^^^^^
  File "/home/airflow/.local/lib/python3.12/site-packages/airflow/models/taskinstance.py", line 273, in _run_raw_task
    TaskInstance._execute_task_with_callbacks(
  File "/home/airflow/.local/lib/python3.12/site-packages/airflow/models/taskinstance.py", line 3158, in _execute_task_with_callbacks
    result = self._execute_task(context, task_orig)
             ^^^^^^^^^^^^^^^^^^^^^^^^^^^^^^^^^^^^^^
  File "/home/airflow/.local/lib/python3.12/site-packages/airflow/models/taskinstance.py", line 3182, in _execute_task
    return _execute_task(self, context, task_orig)
           ^^^^^^^^^^^^^^^^^^^^^^^^^^^^^^^^^^^^^^^
  File "/home/airflow/.local/lib/python3.12/site-packages/airflow/models/taskinstance.py", line 767, in _execute_task
    result = _execute_callable(context=context, **execute_callable_kwargs)
             ^^^^^^^^^^^^^^^^^^^^^^^^^^^^^^^^^^^^^^^^^^^^^^^^^^^^^^^^^^^^^
  File "/home/airflow/.local/lib/python3.12/site-packages/airflow/models/taskinstance.py", line 733, in _execute_callable
    return ExecutionCallableRunner(
           ^^^^^^^^^^^^^^^^^^^^^^^^
  File "/home/airflow/.local/lib/python3.12/site-packages/airflow/utils/operator_helpers.py", line 252, in run
    return self.func(*args, **kwargs)
           ^^^^^^^^^^^^^^^^^^^^^^^^^^
  File "/home/airflow/.local/lib/python3.12/site-packages/airflow/models/baseoperator.py", line 406, in wrapper
    return func(self, *args, **kwargs)
           ^^^^^^^^^^^^^^^^^^^^^^^^^^^
  File "/home/airflow/.local/lib/python3.12/site-packages/airflow/operators/python.py", line 238, in execute
    return_value = self.execute_callable()
                   ^^^^^^^^^^^^^^^^^^^^^^^
  File "/home/airflow/.local/lib/python3.12/site-packages/airflow/operators/python.py", line 256, in execute_callable
    return runner.run(*self.op_args, **self.op_kwargs)
           ^^^^^^^^^^^^^^^^^^^^^^^^^^^^^^^^^^^^^^^^^^^
  File "/home/airflow/.local/lib/python3.12/site-packages/airflow/utils/operator_helpers.py", line 252, in run
    return self.func(*args, **kwargs)
           ^^^^^^^^^^^^^^^^^^^^^^^^^^
  File "/opt/airflow/dags/emailalert_dag.py", line 104, in sample_task
    raise ValueError("This task is meant to fail for testing purposes")
ValueError: This task is meant to fail for testing purposes
[2024-11-10T15:47:08.972+0000] {local_task_job_runner.py:266} INFO - Task exited with return code 1
[2024-11-10T15:47:08.984+0000] {taskinstance.py:3900} INFO - 0 downstream tasks scheduled from follow-on schedule check
[2024-11-10T15:47:08.985+0000] {local_task_job_runner.py:245} INFO - ::endgroup::
